ge_url": "", "line_id": "4021392486", "total_quantity": 1}]
INFO:werkzeug:172.31.128.10 - - [18/Mar/2025 19:13:18] "GET / HTTP/1.1" 200 -
INFO:werkzeug:172.31.128.10 - - [18/Mar/2025 19:13:18] "GET /static/logo/gullu.png HTTP/1.1" 304 -
INFO:werkzeug:172.31.128.10 - - [18/Mar/2025 19:13:18] "GET /static/images/0198523701424.jpg HTTP/1.1" 304 -
2025-03-18 19:14:01 ERROR [app] Exception on /kar_analiz_sayfasi [GET]
Traceback (most recent call last):
  File "/home/runner/workspace/.pythonlibs/lib/python3.11/site-packages/flask/app.py", line 1473, in wsgi_app
    response = self.full_dispatch_request()
               ^^^^^^^^^^^^^^^^^^^^^^^^^^^^
  File "/home/runner/workspace/.pythonlibs/lib/python3.11/site-packages/flask/app.py", line 882, in full_dispatch_request
    rv = self.handle_user_exception(e)
         ^^^^^^^^^^^^^^^^^^^^^^^^^^^^^
  File "/home/runner/workspace/.pythonlibs/lib/python3.11/site-packages/flask_cors/extension.py", line 176, in wrapped_function
    return cors_after_request(app.make_response(f(*args, **kwargs)))
                                                ^^^^^^^^^^^^^^^^^^
  File "/home/runner/workspace/.pythonlibs/lib/python3.11/site-packages/flask/app.py", line 880, in full_dispatch_request
    rv = self.dispatch_request()
         ^^^^^^^^^^^^^^^^^^^^^^^
  File "/home/runner/workspace/.pythonlibs/lib/python3.11/site-packages/flask/app.py", line 865, in dispatch_request
    return self.ensure_sync(self.view_functions[rule.endpoint])(**view_args)  # type: ignore[no-any-return]
           ^^^^^^^^^^^^^^^^^^^^^^^^^^^^^^^^^^^^^^^^^^^^^^^^^^^^^^^^^^^^^^^^^
  File "/home/runner/workspace/kar_maliyet.py", line 89, in kar_analiz_sayfasi
    net_kar, urun_maliyeti = hesapla_kar(siparis)
                             ^^^^^^^^^^^^^^^^^^^^
  File "/home/runner/workspace/kar_maliyet.py", line 25, in hesapla_kar
    urun = db.session.query(Product).filter_by(barcode=birincil_barkod).first()
                            ^^^^^^^
NameError: name 'Product' is not defined
ERROR:app:Exception on /kar_analiz_sayfasi [GET]
Traceback (most recent call last):
  File "/home/runner/workspace/.pythonlibs/lib/python3.11/site-packages/flask/app.py", line 1473, in wsgi_app
    response = self.full_dispatch_request()
               ^^^^^^^^^^^^^^^^^^^^^^^^^^^^
  File "/home/runner/workspace/.pythonlibs/lib/python3.11/site-packages/flask/app.py", line 882, in full_dispatch_request
    rv = self.handle_user_exception(e)
         ^^^^^^^^^^^^^^^^^^^^^^^^^^^^^
  File "/home/runner/workspace/.pythonlibs/lib/python3.11/site-packages/flask_cors/extension.py", line 176, in wrapped_function
    return cors_after_request(app.make_response(f(*args, **kwargs)))
                                                ^^^^^^^^^^^^^^^^^^
  File "/home/runner/workspace/.pythonlibs/lib/python3.11/site-packages/flask/app.py", line 880, in full_dispatch_request
    rv = self.dispatch_request()
         ^^^^^^^^^^^^^^^^^^^^^^^
  File "/home/runner/workspace/.pythonlibs/lib/python3.11/site-packages/flask/app.py", line 865, in dispatch_request
    return self.ensure_sync(self.view_functions[rule.endpoint])(**view_args)  # type: ignore[no-any-return]
           ^^^^^^^^^^^^^^^^^^^^^^^^^^^^^^^^^^^^^^^^^^^^^^^^^^^^^^^^^^^^^^^^^
  File "/home/runner/workspace/kar_maliyet.py", line 89, in kar_analiz_sayfasi
    net_kar, urun_maliyeti = hesapla_kar(siparis)
                             ^^^^^^^^^^^^^^^^^^^^
  File "/home/runner/workspace/kar_maliyet.py", line 25, in hesapla_kar
    urun = db.session.query(Product).filter_by(barcode=birincil_barkod).first()
                            ^^^^^^^
NameError: name 'Product' is not defined
INFO:werkzeug:172.31.128.10 - - [18/Mar/2025 19:14:01] "GET /kar_analiz_sayfasi HTTP/1.1" 500 -
