ERROR:app:Exception on /siparis_fisi/olustur [POST]
Traceback (most recent call last):
  File "/home/runner/Siparis-Yonetim/.pythonlibs/lib/python3.11/site-packages/sqlalchemy/engine/base.py", line 1967, in _exec_single_context
    self.dialect.do_execute(
  File "/home/runner/Siparis-Yonetim/.pythonlibs/lib/python3.11/site-packages/sqlalchemy/engine/default.py", line 941, in do_execute
    cursor.execute(statement, parameters)
psycopg2.errors.NotNullViolation: null value in column "urun_model_kodu" of relation "siparis_fisi" violates not-null constraint
DETAIL:  Failing row contains (18, null, null, 0, 0, 0, 0, 0, 0, 0, null, null, 0.00, 2024-12-22 20:20:20.765166, null).


The above exception was the direct cause of the following exception:

Traceback (most recent call last):
  File "/home/runner/Siparis-Yonetim/.pythonlibs/lib/python3.11/site-packages/flask/app.py", line 1473, in wsgi_app
    response = self.full_dispatch_request()
               ^^^^^^^^^^^^^^^^^^^^^^^^^^^^
  File "/home/runner/Siparis-Yonetim/.pythonlibs/lib/python3.11/site-packages/flask/app.py", line 882, in full_dispatch_request
    rv = self.handle_user_exception(e)
         ^^^^^^^^^^^^^^^^^^^^^^^^^^^^^
  File "/home/runner/Siparis-Yonetim/.pythonlibs/lib/python3.11/site-packages/flask/app.py", line 880, in full_dispatch_request
    rv = self.dispatch_request()
         ^^^^^^^^^^^^^^^^^^^^^^^
  File "/home/runner/Siparis-Yonetim/.pythonlibs/lib/python3.11/site-packages/flask/app.py", line 865, in dispatch_request
    return self.ensure_sync(self.view_functions[rule.endpoint])(**view_args)  # type: ignore[no-any-return]
           ^^^^^^^^^^^^^^^^^^^^^^^^^^^^^^^^^^^^^^^^^^^^^^^^^^^^^^^^^^^^^^^^^
  File "/home/runner/Siparis-Yonetim/siparis_fisi.py", line 68, in siparis_fisi_olustur
    db.session.flush()  # siparis_id'yi almak i√ßin flush
    ^^^^^^^^^^^^^^^^^^
  File "/home/runner/Siparis-Yonetim/.pythonlibs/lib/python3.11/site-packages/sqlalchemy/orm/scoping.py", line 937, in flush
    return self._proxied.flush(objects=objects)
           ^^^^^^^^^^^^^^^^^^^^^^^^^^^^^^^^^^^^
  File "/home/runner/Siparis-Yonetim/.pythonlibs/lib/python3.11/site-packages/sqlalchemy/orm/session.py", line 4352, in flush
    self._flush(objects)
  File "/home/runner/Siparis-Yonetim/.pythonlibs/lib/python3.11/site-packages/sqlalchemy/orm/session.py", line 4487, in _flush
    with util.safe_reraise():
  File "/home/runner/Siparis-Yonetim/.pythonlibs/lib/python3.11/site-packages/sqlalchemy/util/langhelpers.py", line 146, in __exit__
    raise exc_value.with_traceback(exc_tb)
  File "/home/runner/Siparis-Yonetim/.pythonlibs/lib/python3.11/site-packages/sqlalchemy/orm/session.py", line 4448, in _flush
    flush_context.execute()
  File "/home/runner/Siparis-Yonetim/.pythonlibs/lib/python3.11/site-packages/sqlalchemy/orm/unitofwork.py", line 466, in execute
    rec.execute(self)
  File "/home/runner/Siparis-Yonetim/.pythonlibs/lib/python3.11/site-packages/sqlalchemy/orm/unitofwork.py", line 642, in execute
    util.preloaded.orm_persistence.save_obj(
  File "/home/runner/Siparis-Yonetim/.pythonlibs/lib/python3.11/site-packages/sqlalchemy/orm/persistence.py", line 93, in save_obj
    _emit_insert_statements(
  File "/home/runner/Siparis-Yonetim/.pythonlibs/lib/python3.11/site-packages/sqlalchemy/orm/persistence.py", line 1233, in _emit_insert_statements
    result = connection.execute(
             ^^^^^^^^^^^^^^^^^^^
  File "/home/runner/Siparis-Yonetim/.pythonlibs/lib/python3.11/site-packages/sqlalchemy/engine/base.py", line 1418, in execute
    return meth(
           ^^^^^
  File "/home/runner/Siparis-Yonetim/.pythonlibs/lib/python3.11/site-packages/sqlalchemy/sql/elements.py", line 515, in _execute_on_connection
    return connection._execute_clauseelement(
           ^^^^^^^^^^^^^^^^^^^^^^^^^^^^^^^^^^
  File "/home/runner/Siparis-Yonetim/.pythonlibs/lib/python3.11/site-packages/sqlalchemy/engine/base.py", line 1640, in _execute_clauseelement
    ret = self._execute_context(
          ^^^^^^^^^^^^^^^^^^^^^^
  File "/home/runner/Siparis-Yonetim/.pythonlibs/lib/python3.11/site-packages/sqlalchemy/engine/base.py", line 1846, in _execute_context
    return self._exec_single_context(
           ^^^^^^^^^^^^^^^^^^^^^^^^^^
  File "/home/runner/Siparis-Yonetim/.pythonlibs/lib/python3.11/site-packages/sqlalchemy/engine/base.py", line 1986, in _exec_single_context
    self._handle_dbapi_exception(
  File "/home/runner/Siparis-Yonetim/.pythonlibs/lib/python3.11/site-packages/sqlalchemy/engine/base.py", line 2355, in _handle_dbapi_exception
    raise sqlalchemy_exception.with_traceback(exc_info[2]) from e
  File "/home/runner/Siparis-Yonetim/.pythonlibs/lib/python3.11/site-packages/sqlalchemy/engine/base.py", line 1967, in _exec_single_context
    self.dialect.do_execute(
  File "/home/runner/Siparis-Yonetim/.pythonlibs/lib/python3.11/site-packages/sqlalchemy/engine/default.py", line 941, in do_execute
    cursor.execute(statement, parameters)
sqlalchemy.exc.IntegrityError: (psycopg2.errors.NotNullViolation) null value in column "urun_model_kodu" of relation "siparis_fisi" violates not-null constraint
DETAIL:  Failing row contains (18, null, null, 0, 0, 0, 0, 0, 0, 0, null, null, 0.00, 2024-12-22 20:20:20.765166, null).

[SQL: INSERT INTO siparis_fisi (created_date, toplam_fiyat) VALUES (%(created_date)s, %(toplam_fiyat)s) RETURNING siparis_fisi.siparis_id]
[parameters: {'created_date': datetime.datetime(2024, 12, 22, 20, 20, 20, 765166), 'toplam_fiyat': 0}]
(Background on this error at: https://sqlalche.me/e/20/gkpj)
INFO:werkzeug:172.31.196.34 - - [22/Dec/2024 20:20:21] "POST /siparis_fisi/olustur HTTP/1.1" 500 -
 